Workbook

Sheet Conduit Data
A1: Panasonic IMC - Manufacturer Catalogue Data | B1: Panasonic IMC - Manufacturer Catalogue Data | C1: Panasonic IMC - Manufacturer Catalogue Data | D1: Panasonic IMC - Manufacturer Catalogue Data | E1: Panasonic IMC - Manufacturer Catalogue Data | F1: Panasonic IMC - Manufacturer Catalogue Data | G1: Panasonic IMC - Manufacturer Catalogue Data | H1: Panasonic IMC - Manufacturer Catalogue Data | I1: Panasonic IMC - Manufacturer Catalogue Data | J1: Panasonic IMC - Manufacturer Catalogue Data | K1: Panasonic IMC - Manufacturer Catalogue Data | L1: Panasonic IMC - Manufacturer Catalogue Data | M1: Panasonic IMC - Manufacturer Catalogue Data | N1: Panasonic IMC - Manufacturer Catalogue Data | O1: Panasonic IMC - Manufacturer Catalogue Data | P1: Panasonic IMC - Manufacturer Catalogue Data | Q1: Panasonic IMC - Manufacturer Catalogue Data
A3: Brand | B3: Series / type | C3: Item No. | D3: Trade size (inch) | E3: Outside diameter (mm) | F3: Minimum wall thickness (mm) | G3: Length (mm) | H3: Nominal weight (kg/pc) | I3: Primary bundle (pcs) | J3: Master bundle (pcs) | K3: ID_screening (mm) | L3: Area_screening (mm2) | M3: Confirmed actual ID (mm) | N3: Confirmed internal area (mm2) | O3: Standard / listing | P3: Source page | Q3: Status / remark
A4: Panasonic | B4: White Conduit IMC | C4: DWM012Y | D4: 1/2 | E4: 20.7 | F4: 1.79 | G4: 3030 | H4: 2.85 | I4: 10 | J4: 300 | K4: =E4-2*F4 -> 17.12 | L4: =PI()*K4^2/4 -> 230.1958 | M4: 17.12 | N4: =IF(M4="","",PI()*M4^2/4) -> 230.1958 | O4: UL 1242; catalogue also shows TIS 770 coverage | P4: PDF page 5 (printed pp. 7-8) | Q4: OPEN - confirm current product/certificate and actual ID
A5: Panasonic | B5: White Conduit IMC | C5: DWM034Y | D5: 3/4 | E5: 26.14 | F5: 1.9 | G5: 3030 | H5: 3.94 | I5: 5 | J5: 250 | K5: =E5-2*F5 -> 22.34 | L5: =PI()*K5^2/4 -> 391.97306 | M5: 22.34 | N5: =IF(M5="","",PI()*M5^2/4) -> 391.97306 | O5: UL 1242; catalogue also shows TIS 770 coverage | P5: PDF page 5 (printed pp. 7-8) | Q5: OPEN - confirm current product/certificate and actual ID
A6: Panasonic | B6: White Conduit IMC | C6: DWM100Y | D6: 1 | E6: 32.77 | F6: 2.16 | G6: 3025 | H6: 5.23 | I6: 5 | J6: 125 | K6: =E6-2*F6 -> 28.45 | L6: =PI()*K6^2/4 -> 635.70324 | M6: 28.45 | N6: =IF(M6="","",PI()*M6^2/4) -> 635.70324 | O6: UL 1242; catalogue also shows TIS 770 coverage | P6: PDF page 5 (printed pp. 7-8) | Q6: OPEN - confirm current product/certificate and actual ID
A7: Panasonic | B7: White Conduit IMC | C7: DWM114Y | D7: 1-1/4 | E7: 41.59 | F7: 2.16 | G7: 3025 | H7: 7.48 | I7: 3 | J7: 75 | K7: =E7-2*F7 -> 37.27 | L7: =PI()*K7^2/4 -> 1090.9596 | M7: 37.27 | N7: =IF(M7="","",PI()*M7^2/4) -> 1090.9596 | O7: UL 1242; catalogue also shows TIS 770 coverage | P7: PDF page 5 (printed pp. 7-8) | Q7: OPEN - confirm current product/certificate and actual ID
A8: Panasonic | B8: White Conduit IMC | C8: DWM112Y | D8: 1-1/2 | E8: 47.81 | F8: 2.29 | G8: 3025 | H8: 8.67 | I8: 3 | J8: 75 | K8: =E8-2*F8 -> 43.23 | L8: =PI()*K8^2/4 -> 1467.7779 | M8: 43.23 | N8: =IF(M8="","",PI()*M8^2/4) -> 1467.7779 | O8: UL 1242; catalogue also shows TIS 770 coverage | P8: PDF page 5 (printed pp. 7-8) | Q8: OPEN - confirm current product/certificate and actual ID
A9: Panasonic | B9: White Conduit IMC | C9: DWM200Y | D9: 2 | E9: 59.93 | F9: 2.41 | G9: 3025 | H9: 11.65 | J9: 50 | K9: =E9-2*F9 -> 55.11 | L9: =PI()*K9^2/4 -> 2385.3423 | M9: 55.11 | N9: =IF(M9="","",PI()*M9^2/4) -> 2385.3423 | O9: UL 1242; catalogue also shows TIS 770 coverage | P9: PDF page 5 (printed pp. 7-8) | Q9: OPEN - confirm current product/certificate and actual ID
A10: Panasonic | B10: White Conduit IMC | C10: DWM212Y | D10: 2-1/2 | E10: 72.56 | F10: 3.56 | G10: 3010 | H10: 18.71 | J10: 40 | K10: =E10-2*F10 -> 65.44 | L10: =PI()*K10^2/4 -> 3363.3841 | M10: 65.44 | N10: =IF(M10="","",PI()*M10^2/4) -> 3363.3841 | O10: UL 1242; catalogue also shows TIS 770 coverage | P10: PDF page 5 (printed pp. 7-8) | Q10: OPEN - confirm current product/certificate and actual ID
A11: Panasonic | B11: White Conduit IMC | C11: DWM300Y | D11: 3 | E11: 88.29 | F11: 3.56 | G11: 3010 | H11: 22.87 | J11: 30 | K11: =E11-2*F11 -> 81.17 | L11: =PI()*K11^2/4 -> 5174.6499 | M11: 81.17 | N11: =IF(M11="","",PI()*M11^2/4) -> 5174.6499 | O11: UL 1242; catalogue also shows TIS 770 coverage | P11: PDF page 5 (printed pp. 7-8) | Q11: OPEN - confirm current product/certificate and actual ID
A12: Panasonic | B12: White Conduit IMC | C12: DWM312Y | D12: 3-1/2 | E12: 100.86 | F12: 3.56 | G12: 3005 | H12: 26.43 | J12: 20 | K12: =E12-2*F12 -> 93.74 | L12: =PI()*K12^2/4 -> 6901.441 | M12: 93.74 | N12: =IF(M12="","",PI()*M12^2/4) -> 6901.441 | O12: UL 1242; catalogue also shows TIS 770 coverage | P12: PDF page 5 (printed pp. 7-8) | Q12: OPEN - confirm current product/certificate and actual ID
A13: Panasonic | B13: White Conduit IMC | C13: DWM400Y | D13: 4 | E13: 113.4 | F13: 3.56 | G13: 3005 | H13: 29.84 | J13: 15 | K13: =E13-2*F13 -> 106.28 | L13: =PI()*K13^2/4 -> 8871.4166 | M13: 106.28 | N13: =IF(M13="","",PI()*M13^2/4) -> 8871.4166 | O13: UL 1242; catalogue also shows TIS 770 coverage | P13: PDF page 5 (printed pp. 7-8) | Q13: OPEN - confirm current product/certificate and actual ID

Sheet 1.IMC Max Count
A1: Maximum Cable Count in Panasonic IMC - EIT Physical Fill Screening | B1: Maximum Cable Count in Panasonic IMC - EIT Physical Fill Screening | C1: Maximum Cable Count in Panasonic IMC - EIT Physical Fill Screening | D1: Maximum Cable Count in Panasonic IMC - EIT Physical Fill Screening | E1: Maximum Cable Count in Panasonic IMC - EIT Physical Fill Screening | F1: Maximum Cable Count in Panasonic IMC - EIT Physical Fill Screening | G1: Maximum Cable Count in Panasonic IMC - EIT Physical Fill Screening | H1: Maximum Cable Count in Panasonic IMC - EIT Physical Fill Screening | I1: Maximum Cable Count in Panasonic IMC - EIT Physical Fill Screening | J1: Maximum Cable Count in Panasonic IMC - EIT Physical Fill Screening | K1: Maximum Cable Count in Panasonic IMC - EIT Physical Fill Screening | L1: Maximum Cable Count in Panasonic IMC - EIT Physical Fill Screening | M1: Maximum Cable Count in Panasonic IMC - EIT Physical Fill Screening | N1: Maximum Cable Count in Panasonic IMC - EIT Physical Fill Screening | O1: Maximum Cable Count in Panasonic IMC - EIT Physical Fill Screening | P1: Maximum Cable Count in Panasonic IMC - EIT Physical Fill Screening
A2: Rev.4: IMC fill screening is governed by the number of cable pieces (Qty). Cores/cable is informational only. The left matrix gives maximum Qty by IMC size; the right matrix uses that left Qty to show total fill %. Actual certified IMC ID is required before IFC. | B2: วสท. 022001-22 ตาราง 5-3: 1 เส้น 53%, 2 เส้น 31%, 3 เส้นขึ้นไป 40%. ตารางนี้แสดงจำนวนสาย/เคเบิลเป็นชิ้น ไม่ใช่จำนวนวงจร และยังไม่รวม ampacity/grouping/bending/pulling checks | C2: วสท. 022001-22 ตาราง 5-3: 1 เส้น 53%, 2 เส้น 31%, 3 เส้นขึ้นไป 40%. ตารางนี้แสดงจำนวนสาย/เคเบิลเป็นชิ้น ไม่ใช่จำนวนวงจร และยังไม่รวม ampacity/grouping/bending/pulling checks | D2: วสท. 022001-22 ตาราง 5-3: 1 เส้น 53%, 2 เส้น 31%, 3 เส้นขึ้นไป 40%. ตารางนี้แสดงจำนวนสาย/เคเบิลเป็นชิ้น ไม่ใช่จำนวนวงจร และยังไม่รวม ampacity/grouping/bending/pulling checks | E2: วสท. 022001-22 ตาราง 5-3: 1 เส้น 53%, 2 เส้น 31%, 3 เส้นขึ้นไป 40%. ตารางนี้แสดงจำนวนสาย/เคเบิลเป็นชิ้น ไม่ใช่จำนวนวงจร และยังไม่รวม ampacity/grouping/bending/pulling checks | F2: วสท. 022001-22 ตาราง 5-3: 1 เส้น 53%, 2 เส้น 31%, 3 เส้นขึ้นไป 40%. ตารางนี้แสดงจำนวนสาย/เคเบิลเป็นชิ้น ไม่ใช่จำนวนวงจร และยังไม่รวม ampacity/grouping/bending/pulling checks | G2: วสท. 022001-22 ตาราง 5-3: 1 เส้น 53%, 2 เส้น 31%, 3 เส้นขึ้นไป 40%. ตารางนี้แสดงจำนวนสาย/เคเบิลเป็นชิ้น ไม่ใช่จำนวนวงจร และยังไม่รวม ampacity/grouping/bending/pulling checks | H2: วสท. 022001-22 ตาราง 5-3: 1 เส้น 53%, 2 เส้น 31%, 3 เส้นขึ้นไป 40%. ตารางนี้แสดงจำนวนสาย/เคเบิลเป็นชิ้น ไม่ใช่จำนวนวงจร และยังไม่รวม ampacity/grouping/bending/pulling checks | I2: วสท. 022001-22 ตาราง 5-3: 1 เส้น 53%, 2 เส้น 31%, 3 เส้นขึ้นไป 40%. ตารางนี้แสดงจำนวนสาย/เคเบิลเป็นชิ้น ไม่ใช่จำนวนวงจร และยังไม่รวม ampacity/grouping/bending/pulling checks | J2: วสท. 022001-22 ตาราง 5-3: 1 เส้น 53%, 2 เส้น 31%, 3 เส้นขึ้นไป 40%. ตารางนี้แสดงจำนวนสาย/เคเบิลเป็นชิ้น ไม่ใช่จำนวนวงจร และยังไม่รวม ampacity/grouping/bending/pulling checks | K2: วสท. 022001-22 ตาราง 5-3: 1 เส้น 53%, 2 เส้น 31%, 3 เส้นขึ้นไป 40%. ตารางนี้แสดงจำนวนสาย/เคเบิลเป็นชิ้น ไม่ใช่จำนวนวงจร และยังไม่รวม ampacity/grouping/bending/pulling checks | L2: วสท. 022001-22 ตาราง 5-3: 1 เส้น 53%, 2 เส้น 31%, 3 เส้นขึ้นไป 40%. ตารางนี้แสดงจำนวนสาย/เคเบิลเป็นชิ้น ไม่ใช่จำนวนวงจร และยังไม่รวม ampacity/grouping/bending/pulling checks | M2: วสท. 022001-22 ตาราง 5-3: 1 เส้น 53%, 2 เส้น 31%, 3 เส้นขึ้นไป 40%. ตารางนี้แสดงจำนวนสาย/เคเบิลเป็นชิ้น ไม่ใช่จำนวนวงจร และยังไม่รวม ampacity/grouping/bending/pulling checks | N2: วสท. 022001-22 ตาราง 5-3: 1 เส้น 53%, 2 เส้น 31%, 3 เส้นขึ้นไป 40%. ตารางนี้แสดงจำนวนสาย/เคเบิลเป็นชิ้น ไม่ใช่จำนวนวงจร และยังไม่รวม ampacity/grouping/bending/pulling checks | O2: วสท. 022001-22 ตาราง 5-3: 1 เส้น 53%, 2 เส้น 31%, 3 เส้นขึ้นไป 40%. ตารางนี้แสดงจำนวนสาย/เคเบิลเป็นชิ้น ไม่ใช่จำนวนวงจร และยังไม่รวม ampacity/grouping/bending/pulling checks | P2: วสท. 022001-22 ตาราง 5-3: 1 เส้น 53%, 2 เส้น 31%, 3 เส้นขึ้นไป 40%. ตารางนี้แสดงจำนวนสาย/เคเบิลเป็นชิ้น ไม่ใช่จำนวนวงจร และยังไม่รวม ampacity/grouping/bending/pulling checks
A3: IMC internal ID เป็น screening = Panasonic catalogue OD - 2 x minimum wall thickness; ต้องเปลี่ยนเป็น actual certified ID ก่อน issue design. ค่า 0 = ใส่ไม่ได้ตาม physical fill ของท่อขนาดนั้น | B3: IMC internal ID เป็น screening = Panasonic catalogue OD - 2 x minimum wall thickness; ต้องเปลี่ยนเป็น actual certified ID ก่อน issue design. ค่า 0 = ใส่ไม่ได้ตาม physical fill ของท่อขนาดนั้น | C3: IMC internal ID เป็น screening = Panasonic catalogue OD - 2 x minimum wall thickness; ต้องเปลี่ยนเป็น actual certified ID ก่อน issue design. ค่า 0 = ใส่ไม่ได้ตาม physical fill ของท่อขนาดนั้น | D3: IMC internal ID เป็น screening = Panasonic catalogue OD - 2 x minimum wall thickness; ต้องเปลี่ยนเป็น actual certified ID ก่อน issue design. ค่า 0 = ใส่ไม่ได้ตาม physical fill ของท่อขนาดนั้น | E3: IMC internal ID เป็น screening = Panasonic catalogue OD - 2 x minimum wall thickness; ต้องเปลี่ยนเป็น actual certified ID ก่อน issue design. ค่า 0 = ใส่ไม่ได้ตาม physical fill ของท่อขนาดนั้น | F3: IMC internal ID เป็น screening = Panasonic catalogue OD - 2 x minimum wall thickness; ต้องเปลี่ยนเป็น actual certified ID ก่อน issue design. ค่า 0 = ใส่ไม่ได้ตาม physical fill ของท่อขนาดนั้น | G3: IMC internal ID เป็น screening = Panasonic catalogue OD - 2 x minimum wall thickness; ต้องเปลี่ยนเป็น actual certified ID ก่อน issue design. ค่า 0 = ใส่ไม่ได้ตาม physical fill ของท่อขนาดนั้น | H3: IMC internal ID เป็น screening = Panasonic catalogue OD - 2 x minimum wall thickness; ต้องเปลี่ยนเป็น actual certified ID ก่อน issue design. ค่า 0 = ใส่ไม่ได้ตาม physical fill ของท่อขนาดนั้น | I3: IMC internal ID เป็น screening = Panasonic catalogue OD - 2 x minimum wall thickness; ต้องเปลี่ยนเป็น actual certified ID ก่อน issue design. ค่า 0 = ใส่ไม่ได้ตาม physical fill ของท่อขนาดนั้น | J3: IMC internal ID เป็น screening = Panasonic catalogue OD - 2 x minimum wall thickness; ต้องเปลี่ยนเป็น actual certified ID ก่อน issue design. ค่า 0 = ใส่ไม่ได้ตาม physical fill ของท่อขนาดนั้น | K3: IMC internal ID เป็น screening = Panasonic catalogue OD - 2 x minimum wall thickness; ต้องเปลี่ยนเป็น actual certified ID ก่อน issue design. ค่า 0 = ใส่ไม่ได้ตาม physical fill ของท่อขนาดนั้น | L3: IMC internal ID เป็น screening = Panasonic catalogue OD - 2 x minimum wall thickness; ต้องเปลี่ยนเป็น actual certified ID ก่อน issue design. ค่า 0 = ใส่ไม่ได้ตาม physical fill ของท่อขนาดนั้น | M3: IMC internal ID เป็น screening = Panasonic catalogue OD - 2 x minimum wall thickness; ต้องเปลี่ยนเป็น actual certified ID ก่อน issue design. ค่า 0 = ใส่ไม่ได้ตาม physical fill ของท่อขนาดนั้น | N3: IMC internal ID เป็น screening = Panasonic catalogue OD - 2 x minimum wall thickness; ต้องเปลี่ยนเป็น actual certified ID ก่อน issue design. ค่า 0 = ใส่ไม่ได้ตาม physical fill ของท่อขนาดนั้น | O3: IMC internal ID เป็น screening = Panasonic catalogue OD - 2 x minimum wall thickness; ต้องเปลี่ยนเป็น actual certified ID ก่อน issue design. ค่า 0 = ใส่ไม่ได้ตาม physical fill ของท่อขนาดนั้น | P3: IMC internal ID เป็น screening = Panasonic catalogue OD - 2 x minimum wall thickness; ต้องเปลี่ยนเป็น actual certified ID ก่อน issue design. ค่า 0 = ใส่ไม่ได้ตาม physical fill ของท่อขนาดนั้น
A4: Qty 1 = 53%, Qty 2 = 31%, Qty 3 or more = 40%
A5: Panasonic IMC trade size | B5: Panasonic IMC trade size | C5: Panasonic IMC trade size | D5: Panasonic IMC trade size | E5: Panasonic IMC trade size | F5: Panasonic IMC trade size | G5: 1/2 in | H5: 3/4 in | I5: 1 in | J5: 1-1/4 in | K5: 1-1/2 in | L5: 2 in | M5: 2-1/2 in | N5: 3 in | O5: 3-1/2 in | P5: 4 in | Q5: Added comparison: total fill at the maximum Qty from the left matrix
A6: Screening internal ID (mm) | B6: Screening internal ID (mm) | C6: Screening internal ID (mm) | D6: Screening internal ID (mm) | E6: Screening internal ID (mm) | F6: Screening internal ID (mm) | G6: ='Conduit Data'!M4 -> 17.12 | H6: ='Conduit Data'!M5 -> 22.34 | I6: ='Conduit Data'!M6 -> 28.45 | J6: ='Conduit Data'!M7 -> 37.27 | K6: ='Conduit Data'!M8 -> 43.23 | L6: ='Conduit Data'!M9 -> 55.11 | M6: ='Conduit Data'!M10 -> 65.44 | N6: ='Conduit Data'!M11 -> 81.17 | O6: ='Conduit Data'!M12 -> 93.74 | P6: ='Conduit Data'!M13 -> 106.28 | R6: Formula = left-table Qty × cable area / IMC internal area. This is the full fill percentage for the Qty shown in the left table, not a one-cable ratio.
A7: Internal area (mm²) | B7: Internal area (mm²) | C7: Internal area (mm²) | D7: Internal area (mm²) | E7: Internal area (mm²) | F7: Internal area (mm²) | G7: =PI()*G6^2/4 -> 230.1958 | H7: =PI()*H6^2/4 -> 391.97306 | I7: =PI()*I6^2/4 -> 635.70324 | J7: =PI()*J6^2/4 -> 1090.9596 | K7: =PI()*K6^2/4 -> 1467.7779 | L7: =PI()*L6^2/4 -> 2385.3423 | M7: =PI()*M6^2/4 -> 3363.3841 | N7: =PI()*N6^2/4 -> 5174.6499 | ... P7: =PI()*P6^2/4 -> 8871.4166
A9: System | B9: Cable family | C9: Cores / cable (info.) | D9: CSA mm² | E9: OD mm | F9: Cable area mm² | G9: 1/2 in | H9: 3/4 in | I9: 1 in | J9: 1-1/4 in | K9: 1-1/2 in | L9: 2 in | M9: 2-1/2 in | N9: 3 in | O9: 3-1/2 in | P9: 4 in | Q9: Cable / row | R9: 1/2 in | S9: 3/4 in | T9: 1 in | U9: 1-1/4 in | V9: 1-1/2 in | W9: 2 in | X9: 2-1/2 in | Y9: 3 in | Z9: 3-1/2 in | AA9: 4 in
A10: PV | B10: Phelps Dodge H1Z2Z2-K 4 mm² | C10: 1 | D10: 4 | E10: =#REF! -> #REF! | F10: =PI()*E10^2/4 -> #REF! | G10: =IF(G$7="",0,IF(INT(0.4*G$7/$F10)>=3,INT(0.4*G$7/$F10),IF(INT(0.31*G$7/$F10)>=2,2,IF(0.53*G$7/$F10>=1,1,0)))) -> #REF! | H10: =IF(H$7="",0,IF(INT(0.4*H$7/$F10)>=3,INT(0.4*H$7/$F10),IF(INT(0.31*H$7/$F10)>=2,2,IF(0.53*H$7/$F10>=1,1,0)))) -> #REF! | I10: =IF(I$7="",0,IF(INT(0.4*I$7/$F10)>=3,INT(0.4*I$7/$F10),IF(INT(0.31*I$7/$F10)>=2,2,IF(0.53*I$7/$F10>=1,1,0)))) -> #REF! | J10: =IF(J$7="",0,IF(INT(0.4*J$7/$F10)>=3,INT(0.4*J$7/$F10),IF(INT(0.31*J$7/$F10)>=2,2,IF(0.53*J$7/$F10>=1,1,0)))) -> #REF! | K10: =IF(K$7="",0,IF(INT(0.4*K$7/$F10)>=3,INT(0.4*K$7/$F10),IF(INT(0.31*K$7/$F10)>=2,2,IF(0.53*K$7/$F10>=1,1,0)))) -> #REF! | L10: =IF(L$7="",0,IF(INT(0.4*L$7/$F10)>=3,INT(0.4*L$7/$F10),IF(INT(0.31*L$7/$F10)>=2,2,IF(0.53*L$7/$F10>=1,1,0)))) -> #REF! | M10: =IF(M$7="",0,IF(INT(0.4*M$7/$F10)>=3,INT(0.4*M$7/$F10),IF(INT(0.31*M$7/$F10)>=2,2,IF(0.53*M$7/$F10>=1,1,0)))) -> #REF! | N10: =IF(N$7="",0,IF(INT(0.4*N$7/$F10)>=3,INT(0.4*N$7/$F10),IF(INT(0.31*N$7/$F10)>=2,2,IF(0.53*N$7/$F10>=1,1,0)))) -> #REF! | ... P10: =IF(P$7="",0,IF(INT(0.4*P$7/$F10)>=3,INT(0.4*P$7/$F10),IF(INT(0.31*P$7/$F10)>=2,2,IF(0.53*P$7/$F10>=1,1,0)))) -> #REF! | Q10: =B10 -> Phelps Dodge H1Z2Z2-K 4 mm² | R10: =IFERROR($G10*$F10/G$7,"") | S10: =IFERROR($H10*$F10/H$7,"") | T10: =IFERROR($I10*$F10/I$7,"") | U10: =IFERROR($J10*$F10/J$7,"") | V10: =IFERROR($K10*$F10/K$7,"") | W10: =IFERROR($L10*$F10/L$7,"") | X10: =IFERROR($M10*$F10/M$7,"") | Y10: =IFERROR($N10*$F10/N$7,"") | Z10: =IFERROR($O10*$F10/O$7,"") | AA10: =IFERROR($P10*$F10/P$7,"")
A11: PV | B11: Phelps Dodge H1Z2Z2-K 6 mm² | C11: 1 | D11: 6 | E11: =#REF! -> #REF! | F11: =PI()*E11^2/4 -> #REF! | G11: =IF(G$7="",0,IF(INT(0.4*G$7/$F11)>=3,INT(0.4*G$7/$F11),IF(INT(0.31*G$7/$F11)>=2,2,IF(0.53*G$7/$F11>=1,1,0)))) -> #REF! | H11: =IF(H$7="",0,IF(INT(0.4*H$7/$F11)>=3,INT(0.4*H$7/$F11),IF(INT(0.31*H$7/$F11)>=2,2,IF(0.53*H$7/$F11>=1,1,0)))) -> #REF! | I11: =IF(I$7="",0,IF(INT(0.4*I$7/$F11)>=3,INT(0.4*I$7/$F11),IF(INT(0.31*I$7/$F11)>=2,2,IF(0.53*I$7/$F11>=1,1,0)))) -> #REF! | J11: =IF(J$7="",0,IF(INT(0.4*J$7/$F11)>=3,INT(0.4*J$7/$F11),IF(INT(0.31*J$7/$F11)>=2,2,IF(0.53*J$7/$F11>=1,1,0)))) -> #REF! | K11: =IF(K$7="",0,IF(INT(0.4*K$7/$F11)>=3,INT(0.4*K$7/$F11),IF(INT(0.31*K$7/$F11)>=2,2,IF(0.53*K$7/$F11>=1,1,0)))) -> #REF! | L11: =IF(L$7="",0,IF(INT(0.4*L$7/$F11)>=3,INT(0.4*L$7/$F11),IF(INT(0.31*L$7/$F11)>=2,2,IF(0.53*L$7/$F11>=1,1,0)))) -> #REF! | M11: =IF(M$7="",0,IF(INT(0.4*M$7/$F11)>=3,INT(0.4*M$7/$F11),IF(INT(0.31*M$7/$F11)>=2,2,IF(0.53*M$7/$F11>=1,1,0)))) -> #REF! | N11: =IF(N$7="",0,IF(INT(0.4*N$7/$F11)>=3,INT(0.4*N$7/$F11),IF(INT(0.31*N$7/$F11)>=2,2,IF(0.53*N$7/$F11>=1,1,0)))) -> #REF! | ... P11: =IF(P$7="",0,IF(INT(0.4*P$7/$F11)>=3,INT(0.4*P$7/$F11),IF(INT(0.31*P$7/$F11)>=2,2,IF(0.53*P$7/$F11>=1,1,0)))) -> #REF! | Q11: =B11 -> Phelps Dodge H1Z2Z2-K 6 mm² | R11: =IFERROR($G11*$F11/G$7,"") | S11: =IFERROR($H11*$F11/H$7,"") | T11: =IFERROR($I11*$F11/I$7,"") | U11: =IFERROR($J11*$F11/J$7,"") | V11: =IFERROR($K11*$F11/K$7,"") | W11: =IFERROR($L11*$F11/L$7,"") | X11: =IFERROR($M11*$F11/M$7,"") | Y11: =IFERROR($N11*$F11/N$7,"") | Z11: =IFERROR($O11*$F11/O$7,"") | AA11: =IFERROR($P11*$F11/P$7,"")
A12: PV | B12: Phelps Dodge H1Z2Z2-K 10 mm² | C12: 1 | D12: 10 | E12: =#REF! -> #REF! | F12: =PI()*E12^2/4 -> #REF! | G12: =IF(G$7="",0,IF(INT(0.4*G$7/$F12)>=3,INT(0.4*G$7/$F12),IF(INT(0.31*G$7/$F12)>=2,2,IF(0.53*G$7/$F12>=1,1,0)))) -> #REF! | H12: =IF(H$7="",0,IF(INT(0.4*H$7/$F12)>=3,INT(0.4*H$7/$F12),IF(INT(0.31*H$7/$F12)>=2,2,IF(0.53*H$7/$F12>=1,1,0)))) -> #REF! | I12: =IF(I$7="",0,IF(INT(0.4*I$7/$F12)>=3,INT(0.4*I$7/$F12),IF(INT(0.31*I$7/$F12)>=2,2,IF(0.53*I$7/$F12>=1,1,0)))) -> #REF! | J12: =IF(J$7="",0,IF(INT(0.4*J$7/$F12)>=3,INT(0.4*J$7/$F12),IF(INT(0.31*J$7/$F12)>=2,2,IF(0.53*J$7/$F12>=1,1,0)))) -> #REF! | K12: =IF(K$7="",0,IF(INT(0.4*K$7/$F12)>=3,INT(0.4*K$7/$F12),IF(INT(0.31*K$7/$F12)>=2,2,IF(0.53*K$7/$F12>=1,1,0)))) -> #REF! | L12: =IF(L$7="",0,IF(INT(0.4*L$7/$F12)>=3,INT(0.4*L$7/$F12),IF(INT(0.31*L$7/$F12)>=2,2,IF(0.53*L$7/$F12>=1,1,0)))) -> #REF! | M12: =IF(M$7="",0,IF(INT(0.4*M$7/$F12)>=3,INT(0.4*M$7/$F12),IF(INT(0.31*M$7/$F12)>=2,2,IF(0.53*M$7/$F12>=1,1,0)))) -> #REF! | N12: =IF(N$7="",0,IF(INT(0.4*N$7/$F12)>=3,INT(0.4*N$7/$F12),IF(INT(0.31*N$7/$F12)>=2,2,IF(0.53*N$7/$F12>=1,1,0)))) -> #REF! | ... P12: =IF(P$7="",0,IF(INT(0.4*P$7/$F12)>=3,INT(0.4*P$7/$F12),IF(INT(0.31*P$7/$F12)>=2,2,IF(0.53*P$7/$F12>=1,1,0)))) -> #REF! | Q12: =B12 -> Phelps Dodge H1Z2Z2-K 10 mm² | R12: =IFERROR($G12*$F12/G$7,"") | S12: =IFERROR($H12*$F12/H$7,"") | T12: =IFERROR($I12*$F12/I$7,"") | U12: =IFERROR($J12*$F12/J$7,"") | V12: =IFERROR($K12*$F12/K$7,"") | W12: =IFERROR($L12*$F12/L$7,"") | X12: =IFERROR($M12*$F12/M$7,"") | Y12: =IFERROR($N12*$F12/N$7,"") | Z12: =IFERROR($O12*$F12/O$7,"") | AA12: =IFERROR($P12*$F12/P$7,"")
A13: PV | B13: Phelps Dodge H1Z2Z2-K 16 mm² | C13: 1 | D13: 16 | E13: =#REF! -> #REF! | F13: =PI()*E13^2/4 -> #REF! | G13: =IF(G$7="",0,IF(INT(0.4*G$7/$F13)>=3,INT(0.4*G$7/$F13),IF(INT(0.31*G$7/$F13)>=2,2,IF(0.53*G$7/$F13>=1,1,0)))) -> #REF! | H13: =IF(H$7="",0,IF(INT(0.4*H$7/$F13)>=3,INT(0.4*H$7/$F13),IF(INT(0.31*H$7/$F13)>=2,2,IF(0.53*H$7/$F13>=1,1,0)))) -> #REF! | I13: =IF(I$7="",0,IF(INT(0.4*I$7/$F13)>=3,INT(0.4*I$7/$F13),IF(INT(0.31*I$7/$F13)>=2,2,IF(0.53*I$7/$F13>=1,1,0)))) -> #REF! | J13: =IF(J$7="",0,IF(INT(0.4*J$7/$F13)>=3,INT(0.4*J$7/$F13),IF(INT(0.31*J$7/$F13)>=2,2,IF(0.53*J$7/$F13>=1,1,0)))) -> #REF! | K13: =IF(K$7="",0,IF(INT(0.4*K$7/$F13)>=3,INT(0.4*K$7/$F13),IF(INT(0.31*K$7/$F13)>=2,2,IF(0.53*K$7/$F13>=1,1,0)))) -> #REF! | L13: =IF(L$7="",0,IF(INT(0.4*L$7/$F13)>=3,INT(0.4*L$7/$F13),IF(INT(0.31*L$7/$F13)>=2,2,IF(0.53*L$7/$F13>=1,1,0)))) -> #REF! | M13: =IF(M$7="",0,IF(INT(0.4*M$7/$F13)>=3,INT(0.4*M$7/$F13),IF(INT(0.31*M$7/$F13)>=2,2,IF(0.53*M$7/$F13>=1,1,0)))) -> #REF! | N13: =IF(N$7="",0,IF(INT(0.4*N$7/$F13)>=3,INT(0.4*N$7/$F13),IF(INT(0.31*N$7/$F13)>=2,2,IF(0.53*N$7/$F13>=1,1,0)))) -> #REF! | ... P13: =IF(P$7="",0,IF(INT(0.4*P$7/$F13)>=3,INT(0.4*P$7/$F13),IF(INT(0.31*P$7/$F13)>=2,2,IF(0.53*P$7/$F13>=1,1,0)))) -> #REF! | Q13: =B13 -> Phelps Dodge H1Z2Z2-K 16 mm² | R13: =IFERROR($G13*$F13/G$7,"") | S13: =IFERROR($H13*$F13/H$7,"") | T13: =IFERROR($I13*$F13/I$7,"") | U13: =IFERROR($J13*$F13/J$7,"") | V13: =IFERROR($K13*$F13/K$7,"") | W13: =IFERROR($L13*$F13/L$7,"") | X13: =IFERROR($M13*$F13/M$7,"") | Y13: =IFERROR($N13*$F13/N$7,"") | Z13: =IFERROR($O13*$F13/O$7,"") | AA13: =IFERROR($P13*$F13/P$7,"")
A14: AC | B14: Phelps Dodge CV/CV-FD-1C | 25 mm² | C14: 1 | D14: 25 | E14: 12 | F14: =PI()*E14^2/4 -> 113.09734 | G14: =IF(G$7="",0,IF(INT(0.4*G$7/$F14)>=3,INT(0.4*G$7/$F14),IF(INT(0.31*G$7/$F14)>=2,2,IF(0.53*G$7/$F14>=1,1,0)))) -> 1 | H14: =IF(H$7="",0,IF(INT(0.4*H$7/$F14)>=3,INT(0.4*H$7/$F14),IF(INT(0.31*H$7/$F14)>=2,2,IF(0.53*H$7/$F14>=1,1,0)))) -> 1 | I14: =IF(I$7="",0,IF(INT(0.4*I$7/$F14)>=3,INT(0.4*I$7/$F14),IF(INT(0.31*I$7/$F14)>=2,2,IF(0.53*I$7/$F14>=1,1,0)))) -> 1 | J14: =IF(J$7="",0,IF(INT(0.4*J$7/$F14)>=3,INT(0.4*J$7/$F14),IF(INT(0.31*J$7/$F14)>=2,2,IF(0.53*J$7/$F14>=1,1,0)))) -> 3 | K14: =IF(K$7="",0,IF(INT(0.4*K$7/$F14)>=3,INT(0.4*K$7/$F14),IF(INT(0.31*K$7/$F14)>=2,2,IF(0.53*K$7/$F14>=1,1,0)))) -> 5 | L14: =IF(L$7="",0,IF(INT(0.4*L$7/$F14)>=3,INT(0.4*L$7/$F14),IF(INT(0.31*L$7/$F14)>=2,2,IF(0.53*L$7/$F14>=1,1,0)))) -> 8 | M14: =IF(M$7="",0,IF(INT(0.4*M$7/$F14)>=3,INT(0.4*M$7/$F14),IF(INT(0.31*M$7/$F14)>=2,2,IF(0.53*M$7/$F14>=1,1,0)))) -> 11 | N14: =IF(N$7="",0,IF(INT(0.4*N$7/$F14)>=3,INT(0.4*N$7/$F14),IF(INT(0.31*N$7/$F14)>=2,2,IF(0.53*N$7/$F14>=1,1,0)))) -> 18 | ... P14: =IF(P$7="",0,IF(INT(0.4*P$7/$F14)>=3,INT(0.4*P$7/$F14),IF(INT(0.31*P$7/$F14)>=2,2,IF(0.53*P$7/$F14>=1,1,0)))) -> 31 | R14: =IFERROR($G14*$F14/G$7,"") -> 0.49130928 | S14: =IFERROR($H14*$F14/H$7,"") -> 0.28853344 | T14: =IFERROR($I14*$F14/I$7,"") -> 0.17790901 | U14: =IFERROR($J14*$F14/J$7,"") -> 0.31100327 | V14: =IFERROR($K14*$F14/K$7,"") -> 0.38526719 | W14: =IFERROR($L14*$F14/L$7,"") -> 0.3793077 | X14: =IFERROR($M14*$F14/M$7,"") -> 0.3698866 | Y14: =IFERROR($N14*$F14/N$7,"") -> 0.39340865 | Z14: =IFERROR($O14*$F14/O$7,"") -> 0.3932999 | AA14: =IFERROR($P14*$F14/P$7,"") -> 0.39520378
A15: AC | B15: Phelps Dodge CV/CV-FD-1C | 35 mm² | C15: 1 | D15: 35 | E15: 13 | F15: =PI()*E15^2/4 -> 132.73229 | G15: =IF(G$7="",0,IF(INT(0.4*G$7/$F15)>=3,INT(0.4*G$7/$F15),IF(INT(0.31*G$7/$F15)>=2,2,IF(0.53*G$7/$F15>=1,1,0)))) -> 0 | H15: =IF(H$7="",0,IF(INT(0.4*H$7/$F15)>=3,INT(0.4*H$7/$F15),IF(INT(0.31*H$7/$F15)>=2,2,IF(0.53*H$7/$F15>=1,1,0)))) -> 1 | I15: =IF(I$7="",0,IF(INT(0.4*I$7/$F15)>=3,INT(0.4*I$7/$F15),IF(INT(0.31*I$7/$F15)>=2,2,IF(0.53*I$7/$F15>=1,1,0)))) -> 1 | J15: =IF(J$7="",0,IF(INT(0.4*J$7/$F15)>=3,INT(0.4*J$7/$F15),IF(INT(0.31*J$7/$F15)>=2,2,IF(0.53*J$7/$F15>=1,1,0)))) -> 3 | K15: =IF(K$7="",0,IF(INT(0.4*K$7/$F15)>=3,INT(0.4*K$7/$F15),IF(INT(0.31*K$7/$F15)>=2,2,IF(0.53*K$7/$F15>=1,1,0)))) -> 4 | L15: =IF(L$7="",0,IF(INT(0.4*L$7/$F15)>=3,INT(0.4*L$7/$F15),IF(INT(0.31*L$7/$F15)>=2,2,IF(0.53*L$7/$F15>=1,1,0)))) -> 7 | M15: =IF(M$7="",0,IF(INT(0.4*M$7/$F15)>=3,INT(0.4*M$7/$F15),IF(INT(0.31*M$7/$F15)>=2,2,IF(0.53*M$7/$F15>=1,1,0)))) -> 10 | N15: =IF(N$7="",0,IF(INT(0.4*N$7/$F15)>=3,INT(0.4*N$7/$F15),IF(INT(0.31*N$7/$F15)>=2,2,IF(0.53*N$7/$F15>=1,1,0)))) -> 15 | ... P15: =IF(P$7="",0,IF(INT(0.4*P$7/$F15)>=3,INT(0.4*P$7/$F15),IF(INT(0.31*P$7/$F15)>=2,2,IF(0.53*P$7/$F15>=1,1,0)))) -> 26 | R15: =IFERROR($G15*$F15/G$7,"") -> 0 | S15: =IFERROR($H15*$F15/H$7,"") -> 0.33862605 | T15: =IFERROR($I15*$F15/I$7,"") -> 0.20879599 | U15: =IFERROR($J15*$F15/J$7,"") -> 0.3649969 | V15: =IFERROR($K15*$F15/K$7,"") -> 0.36172308 | W15: =IFERROR($L15*$F15/L$7,"") -> 0.38951476 | X15: =IFERROR($M15*$F15/M$7,"") -> 0.39463911 | Y15: =IFERROR($N15*$F15/N$7,"") -> 0.3847573 | Z15: =IFERROR($O15*$F15/O$7,"") -> 0.38465094 | AA15: =IFERROR($P15*$F15/P$7,"") -> 0.38900659
A16: AC | B16: Phelps Dodge CV/CV-FD-1C | 50 mm² | C16: 1 | D16: 50 | E16: 15 | F16: =PI()*E16^2/4 -> 176.71459 | G16: =IF(G$7="",0,IF(INT(0.4*G$7/$F16)>=3,INT(0.4*G$7/$F16),IF(INT(0.31*G$7/$F16)>=2,2,IF(0.53*G$7/$F16>=1,1,0)))) -> 0 | H16: =IF(H$7="",0,IF(INT(0.4*H$7/$F16)>=3,INT(0.4*H$7/$F16),IF(INT(0.31*H$7/$F16)>=2,2,IF(0.53*H$7/$F16>=1,1,0)))) -> 1 | I16: =IF(I$7="",0,IF(INT(0.4*I$7/$F16)>=3,INT(0.4*I$7/$F16),IF(INT(0.31*I$7/$F16)>=2,2,IF(0.53*I$7/$F16>=1,1,0)))) -> 1 | J16: =IF(J$7="",0,IF(INT(0.4*J$7/$F16)>=3,INT(0.4*J$7/$F16),IF(INT(0.31*J$7/$F16)>=2,2,IF(0.53*J$7/$F16>=1,1,0)))) -> 1 | K16: =IF(K$7="",0,IF(INT(0.4*K$7/$F16)>=3,INT(0.4*K$7/$F16),IF(INT(0.31*K$7/$F16)>=2,2,IF(0.53*K$7/$F16>=1,1,0)))) -> 3 | L16: =IF(L$7="",0,IF(INT(0.4*L$7/$F16)>=3,INT(0.4*L$7/$F16),IF(INT(0.31*L$7/$F16)>=2,2,IF(0.53*L$7/$F16>=1,1,0)))) -> 5 | M16: =IF(M$7="",0,IF(INT(0.4*M$7/$F16)>=3,INT(0.4*M$7/$F16),IF(INT(0.31*M$7/$F16)>=2,2,IF(0.53*M$7/$F16>=1,1,0)))) -> 7 | N16: =IF(N$7="",0,IF(INT(0.4*N$7/$F16)>=3,INT(0.4*N$7/$F16),IF(INT(0.31*N$7/$F16)>=2,2,IF(0.53*N$7/$F16>=1,1,0)))) -> 11 | ... P16: =IF(P$7="",0,IF(INT(0.4*P$7/$F16)>=3,INT(0.4*P$7/$F16),IF(INT(0.31*P$7/$F16)>=2,2,IF(0.53*P$7/$F16>=1,1,0)))) -> 20 | R16: =IFERROR($G16*$F16/G$7,"") -> 0 | S16: =IFERROR($H16*$F16/H$7,"") -> 0.4508335 | T16: =IFERROR($I16*$F16/I$7,"") -> 0.27798283 | U16: =IFERROR($J16*$F16/J$7,"") -> 0.16198087 | V16: =IFERROR($K16*$F16/K$7,"") -> 0.36118799 | W16: =IFERROR($L16*$F16/L$7,"") -> 0.37041767 | X16: =IFERROR($M16*$F16/M$7,"") -> 0.36778497 | Y16: =IFERROR($N16*$F16/N$7,"") -> 0.37565062 | Z16: =IFERROR($O16*$F16/O$7,"") -> 0.38408193 | AA16: =IFERROR($P16*$F16/P$7,"") -> 0.39839091
A17: AC | B17: Phelps Dodge CV/CV-FD-1C | 70 mm² | C17: 1 | D17: 70 | E17: 16 | F17: =PI()*E17^2/4 -> 201.06193 | G17: =IF(G$7="",0,IF(INT(0.4*G$7/$F17)>=3,INT(0.4*G$7/$F17),IF(INT(0.31*G$7/$F17)>=2,2,IF(0.53*G$7/$F17>=1,1,0)))) -> 0 | H17: =IF(H$7="",0,IF(INT(0.4*H$7/$F17)>=3,INT(0.4*H$7/$F17),IF(INT(0.31*H$7/$F17)>=2,2,IF(0.53*H$7/$F17>=1,1,0)))) -> 1 | I17: =IF(I$7="",0,IF(INT(0.4*I$7/$F17)>=3,INT(0.4*I$7/$F17),IF(INT(0.31*I$7/$F17)>=2,2,IF(0.53*I$7/$F17>=1,1,0)))) -> 1 | J17: =IF(J$7="",0,IF(INT(0.4*J$7/$F17)>=3,INT(0.4*J$7/$F17),IF(INT(0.31*J$7/$F17)>=2,2,IF(0.53*J$7/$F17>=1,1,0)))) -> 1 | K17: =IF(K$7="",0,IF(INT(0.4*K$7/$F17)>=3,INT(0.4*K$7/$F17),IF(INT(0.31*K$7/$F17)>=2,2,IF(0.53*K$7/$F17>=1,1,0)))) -> 2 | L17: =IF(L$7="",0,IF(INT(0.4*L$7/$F17)>=3,INT(0.4*L$7/$F17),IF(INT(0.31*L$7/$F17)>=2,2,IF(0.53*L$7/$F17>=1,1,0)))) -> 4 | M17: =IF(M$7="",0,IF(INT(0.4*M$7/$F17)>=3,INT(0.4*M$7/$F17),IF(INT(0.31*M$7/$F17)>=2,2,IF(0.53*M$7/$F17>=1,1,0)))) -> 6 | N17: =IF(N$7="",0,IF(INT(0.4*N$7/$F17)>=3,INT(0.4*N$7/$F17),IF(INT(0.31*N$7/$F17)>=2,2,IF(0.53*N$7/$F17>=1,1,0)))) -> 10 | ... P17: =IF(P$7="",0,IF(INT(0.4*P$7/$F17)>=3,INT(0.4*P$7/$F17),IF(INT(0.31*P$7/$F17)>=2,2,IF(0.53*P$7/$F17>=1,1,0)))) -> 17 | R17: =IFERROR($G17*$F17/G$7,"") -> 0 | S17: =IFERROR($H17*$F17/H$7,"") -> 0.51294834 | T17: =IFERROR($I17*$F17/I$7,"") -> 0.31628269 | U17: =IFERROR($J17*$F17/J$7,"") -> 0.18429824 | V17: =IFERROR($K17*$F17/K$7,"") -> 0.27396778 | W17: =IFERROR($L17*$F17/L$7,"") -> 0.3371624 | X17: =IFERROR($M17*$F17/M$7,"") -> 0.35867791 | Y17: =IFERROR($N17*$F17/N$7,"") -> 0.38855175 | Z17: =IFERROR($O17*$F17/O$7,"") -> 0.37873324 | AA17: =IFERROR($P17*$F17/P$7,"") -> 0.38528828
A18: AC | B18: Phelps Dodge CV/CV-FD-1C | 95 mm² | C18: 1 | D18: 95 | E18: 18 | F18: =PI()*E18^2/4 -> 254.469 | G18: =IF(G$7="",0,IF(INT(0.4*G$7/$F18)>=3,INT(0.4*G$7/$F18),IF(INT(0.31*G$7/$F18)>=2,2,IF(0.53*G$7/$F18>=1,1,0)))) -> 0 | H18: =IF(H$7="",0,IF(INT(0.4*H$7/$F18)>=3,INT(0.4*H$7/$F18),IF(INT(0.31*H$7/$F18)>=2,2,IF(0.53*H$7/$F18>=1,1,0)))) -> 0 | I18: =IF(I$7="",0,IF(INT(0.4*I$7/$F18)>=3,INT(0.4*I$7/$F18),IF(INT(0.31*I$7/$F18)>=2,2,IF(0.53*I$7/$F18>=1,1,0)))) -> 1 | J18: =IF(J$7="",0,IF(INT(0.4*J$7/$F18)>=3,INT(0.4*J$7/$F18),IF(INT(0.31*J$7/$F18)>=2,2,IF(0.53*J$7/$F18>=1,1,0)))) -> 1 | K18: =IF(K$7="",0,IF(INT(0.4*K$7/$F18)>=3,INT(0.4*K$7/$F18),IF(INT(0.31*K$7/$F18)>=2,2,IF(0.53*K$7/$F18>=1,1,0)))) -> 1 | L18: =IF(L$7="",0,IF(INT(0.4*L$7/$F18)>=3,INT(0.4*L$7/$F18),IF(INT(0.31*L$7/$F18)>=2,2,IF(0.53*L$7/$F18>=1,1,0)))) -> 3 | M18: =IF(M$7="",0,IF(INT(0.4*M$7/$F18)>=3,INT(0.4*M$7/$F18),IF(INT(0.31*M$7/$F18)>=2,2,IF(0.53*M$7/$F18>=1,1,0)))) -> 5 | N18: =IF(N$7="",0,IF(INT(0.4*N$7/$F18)>=3,INT(0.4*N$7/$F18),IF(INT(0.31*N$7/$F18)>=2,2,IF(0.53*N$7/$F18>=1,1,0)))) -> 8 | ... P18: =IF(P$7="",0,IF(INT(0.4*P$7/$F18)>=3,INT(0.4*P$7/$F18),IF(INT(0.31*P$7/$F18)>=2,2,IF(0.53*P$7/$F18>=1,1,0)))) -> 13 | R18: =IFERROR($G18*$F18/G$7,"") -> 0 | S18: =IFERROR($H18*$F18/H$7,"") -> 0 | T18: =IFERROR($I18*$F18/I$7,"") -> 0.40029528 | U18: =IFERROR($J18*$F18/J$7,"") -> 0.23325246 | V18: =IFERROR($K18*$F18/K$7,"") -> 0.17337024 | W18: =IFERROR($L18*$F18/L$7,"") -> 0.32004087 | X18: =IFERROR($M18*$F18/M$7,"") -> 0.37829311 | Y18: =IFERROR($N18*$F18/N$7,"") -> 0.39340865 | Z18: =IFERROR($O18*$F18/O$7,"") -> 0.36871866 | AA18: =IFERROR($P18*$F18/P$7,"") -> 0.37289389
A19: AC | B19: Phelps Dodge CV/CV-FD-1C | 120 mm² | C19: 1 | D19: 120 | E19: 20 | F19: =PI()*E19^2/4 -> 314.15927 | G19: =IF(G$7="",0,IF(INT(0.4*G$7/$F19)>=3,INT(0.4*G$7/$F19),IF(INT(0.31*G$7/$F19)>=2,2,IF(0.53*G$7/$F19>=1,1,0)))) -> 0 | H19: =IF(H$7="",0,IF(INT(0.4*H$7/$F19)>=3,INT(0.4*H$7/$F19),IF(INT(0.31*H$7/$F19)>=2,2,IF(0.53*H$7/$F19>=1,1,0)))) -> 0 | I19: =IF(I$7="",0,IF(INT(0.4*I$7/$F19)>=3,INT(0.4*I$7/$F19),IF(INT(0.31*I$7/$F19)>=2,2,IF(0.53*I$7/$F19>=1,1,0)))) -> 1 | J19: =IF(J$7="",0,IF(INT(0.4*J$7/$F19)>=3,INT(0.4*J$7/$F19),IF(INT(0.31*J$7/$F19)>=2,2,IF(0.53*J$7/$F19>=1,1,0)))) -> 1 | K19: =IF(K$7="",0,IF(INT(0.4*K$7/$F19)>=3,INT(0.4*K$7/$F19),IF(INT(0.31*K$7/$F19)>=2,2,IF(0.53*K$7/$F19>=1,1,0)))) -> 1 | L19: =IF(L$7="",0,IF(INT(0.4*L$7/$F19)>=3,INT(0.4*L$7/$F19),IF(INT(0.31*L$7/$F19)>=2,2,IF(0.53*L$7/$F19>=1,1,0)))) -> 3 | M19: =IF(M$7="",0,IF(INT(0.4*M$7/$F19)>=3,INT(0.4*M$7/$F19),IF(INT(0.31*M$7/$F19)>=2,2,IF(0.53*M$7/$F19>=1,1,0)))) -> 4 | N19: =IF(N$7="",0,IF(INT(0.4*N$7/$F19)>=3,INT(0.4*N$7/$F19),IF(INT(0.31*N$7/$F19)>=2,2,IF(0.53*N$7/$F19>=1,1,0)))) -> 6 | ... P19: =IF(P$7="",0,IF(INT(0.4*P$7/$F19)>=3,INT(0.4*P$7/$F19),IF(INT(0.31*P$7/$F19)>=2,2,IF(0.53*P$7/$F19>=1,1,0)))) -> 11 | R19: =IFERROR($G19*$F19/G$7,"") -> 0 | S19: =IFERROR($H19*$F19/H$7,"") -> 0 | T19: =IFERROR($I19*$F19/I$7,"") -> 0.4941917 | U19: =IFERROR($J19*$F19/J$7,"") -> 0.28796599 | V19: =IFERROR($K19*$F19/K$7,"") -> 0.21403733 | W19: =IFERROR($L19*$F19/L$7,"") -> 0.39511219 | X19: =IFERROR($M19*$F19/M$7,"") -> 0.37362283 | Y19: =IFERROR($N19*$F19/N$7,"") -> 0.36426727 | Z19: =IFERROR($O19*$F19/O$7,"") -> 0.36416657 | AA19: =IFERROR($P19*$F19/P$7,"") -> 0.38953778
A20: AC | B20: Phelps Dodge CV/CV-FD-1C | 150 mm² | C20: 1 | D20: 150 | E20: 22 | F20: =PI()*E20^2/4 -> 380.13271 | G20: =IF(INT(0.4*G$7/$F20)>=3,INT(0.4*G$7/$F20),IF(INT(0.31*G$7/$F20)>=2,2,IF(0.53*G$7/$F20>=1,1,0))) -> 0 | H20: =IF(INT(0.4*H$7/$F20)>=3,INT(0.4*H$7/$F20),IF(INT(0.31*H$7/$F20)>=2,2,IF(0.53*H$7/$F20>=1,1,0))) -> 0 | I20: =IF(INT(0.4*I$7/$F20)>=3,INT(0.4*I$7/$F20),IF(INT(0.31*I$7/$F20)>=2,2,IF(0.53*I$7/$F20>=1,1,0))) -> 0 | J20: =IF(INT(0.4*J$7/$F20)>=3,INT(0.4*J$7/$F20),IF(INT(0.31*J$7/$F20)>=2,2,IF(0.53*J$7/$F20>=1,1,0))) -> 1 | K20: =IF(INT(0.4*K$7/$F20)>=3,INT(0.4*K$7/$F20),IF(INT(0.31*K$7/$F20)>=2,2,IF(0.53*K$7/$F20>=1,1,0))) -> 1 | L20: =IF(INT(0.4*L$7/$F20)>=3,INT(0.4*L$7/$F20),IF(INT(0.31*L$7/$F20)>=2,2,IF(0.53*L$7/$F20>=1,1,0))) -> 1 | M20: =IF(INT(0.4*M$7/$F20)>=3,INT(0.4*M$7/$F20),IF(INT(0.31*M$7/$F20)>=2,2,IF(0.53*M$7/$F20>=1,1,0))) -> 3 | N20: =IF(INT(0.4*N$7/$F20)>=3,INT(0.4*N$7/$F20),IF(INT(0.31*N$7/$F20)>=2,2,IF(0.53*N$7/$F20>=1,1,0))) -> 5 | ... P20: =IF(INT(0.4*P$7/$F20)>=3,INT(0.4*P$7/$F20),IF(INT(0.31*P$7/$F20)>=2,2,IF(0.53*P$7/$F20>=1,1,0))) -> 9 | R20: =IFERROR($G20*$F20/G$7,"") -> 0 | S20: =IFERROR($H20*$F20/H$7,"") -> 0 | T20: =IFERROR($I20*$F20/I$7,"") -> 0 | U20: =IFERROR($J20*$F20/J$7,"") -> 0.34843885 | V20: =IFERROR($K20*$F20/K$7,"") -> 0.25898517 | W20: =IFERROR($L20*$F20/L$7,"") -> 0.15936191 | X20: =IFERROR($M20*$F20/M$7,"") -> 0.33906271 | Y20: =IFERROR($N20*$F20/N$7,"") -> 0.36730283 | Z20: =IFERROR($O20*$F20/O$7,"") -> 0.38556136 | AA20: =IFERROR($P20*$F20/P$7,"") -> 0.3856424
A21: AC | B21: Phelps Dodge CV/CV-FD-1C | 185 mm² | C21: 1 | D21: 185 | E21: 24 | F21: =PI()*E21^2/4 -> 452.38934 | G21: =IF(INT(0.4*G$7/$F21)>=3,INT(0.4*G$7/$F21),IF(INT(0.31*G$7/$F21)>=2,2,IF(0.53*G$7/$F21>=1,1,0))) -> 0 | H21: =IF(INT(0.4*H$7/$F21)>=3,INT(0.4*H$7/$F21),IF(INT(0.31*H$7/$F21)>=2,2,IF(0.53*H$7/$F21>=1,1,0))) -> 0 | I21: =IF(INT(0.4*I$7/$F21)>=3,INT(0.4*I$7/$F21),IF(INT(0.31*I$7/$F21)>=2,2,IF(0.53*I$7/$F21>=1,1,0))) -> 0 | J21: =IF(INT(0.4*J$7/$F21)>=3,INT(0.4*J$7/$F21),IF(INT(0.31*J$7/$F21)>=2,2,IF(0.53*J$7/$F21>=1,1,0))) -> 1 | K21: =IF(INT(0.4*K$7/$F21)>=3,INT(0.4*K$7/$F21),IF(INT(0.31*K$7/$F21)>=2,2,IF(0.53*K$7/$F21>=1,1,0))) -> 1 | L21: =IF(INT(0.4*L$7/$F21)>=3,INT(0.4*L$7/$F21),IF(INT(0.31*L$7/$F21)>=2,2,IF(0.53*L$7/$F21>=1,1,0))) -> 1 | M21: =IF(INT(0.4*M$7/$F21)>=3,INT(0.4*M$7/$F21),IF(INT(0.31*M$7/$F21)>=2,2,IF(0.53*M$7/$F21>=1,1,0))) -> 2 | N21: =IF(INT(0.4*N$7/$F21)>=3,INT(0.4*N$7/$F21),IF(INT(0.31*N$7/$F21)>=2,2,IF(0.53*N$7/$F21>=1,1,0))) -> 4 | ... P21: =IF(INT(0.4*P$7/$F21)>=3,INT(0.4*P$7/$F21),IF(INT(0.31*P$7/$F21)>=2,2,IF(0.53*P$7/$F21>=1,1,0))) -> 7 | R21: =IFERROR($G21*$F21/G$7,"") -> 0 | S21: =IFERROR($H21*$F21/H$7,"") -> 0 | T21: =IFERROR($I21*$F21/I$7,"") -> 0 | U21: =IFERROR($J21*$F21/J$7,"") -> 0.41467103 | V21: =IFERROR($K21*$F21/K$7,"") -> 0.30821375 | W21: =IFERROR($L21*$F21/L$7,"") -> 0.18965385 | X21: =IFERROR($M21*$F21/M$7,"") -> 0.26900843 | Y21: =IFERROR($N21*$F21/N$7,"") -> 0.34969658 | Z21: =IFERROR($O21*$F21/O$7,"") -> 0.3932999 | AA21: =IFERROR($P21*$F21/P$7,"") -> 0.35695826
A22: AC | B22: Phelps Dodge CV/CV-FD-1C | 240 mm² | C22: 1 | D22: 240 | E22: 27 | F22: =PI()*E22^2/4 -> 572.55526 | G22: =IF(INT(0.4*G$7/$F22)>=3,INT(0.4*G$7/$F22),IF(INT(0.31*G$7/$F22)>=2,2,IF(0.53*G$7/$F22>=1,1,0))) -> 0 | H22: =IF(INT(0.4*H$7/$F22)>=3,INT(0.4*H$7/$F22),IF(INT(0.31*H$7/$F22)>=2,2,IF(0.53*H$7/$F22>=1,1,0))) -> 0 | I22: =IF(INT(0.4*I$7/$F22)>=3,INT(0.4*I$7/$F22),IF(INT(0.31*I$7/$F22)>=2,2,IF(0.53*I$7/$F22>=1,1,0))) -> 0 | J22: =IF(INT(0.4*J$7/$F22)>=3,INT(0.4*J$7/$F22),IF(INT(0.31*J$7/$F22)>=2,2,IF(0.53*J$7/$F22>=1,1,0))) -> 1 | K22: =IF(INT(0.4*K$7/$F22)>=3,INT(0.4*K$7/$F22),IF(INT(0.31*K$7/$F22)>=2,2,IF(0.53*K$7/$F22>=1,1,0))) -> 1 | L22: =IF(INT(0.4*L$7/$F22)>=3,INT(0.4*L$7/$F22),IF(INT(0.31*L$7/$F22)>=2,2,IF(0.53*L$7/$F22>=1,1,0))) -> 1 | M22: =IF(INT(0.4*M$7/$F22)>=3,INT(0.4*M$7/$F22),IF(INT(0.31*M$7/$F22)>=2,2,IF(0.53*M$7/$F22>=1,1,0))) -> 1 | N22: =IF(INT(0.4*N$7/$F22)>=3,INT(0.4*N$7/$F22),IF(INT(0.31*N$7/$F22)>=2,2,IF(0.53*N$7/$F22>=1,1,0))) -> 3 | ... P22: =IF(INT(0.4*P$7/$F22)>=3,INT(0.4*P$7/$F22),IF(INT(0.31*P$7/$F22)>=2,2,IF(0.53*P$7/$F22>=1,1,0))) -> 6 | R22: =IFERROR($G22*$F22/G$7,"") -> 0 | S22: =IFERROR($H22*$F22/H$7,"") -> 0 | T22: =IFERROR($I22*$F22/I$7,"") -> 0 | U22: =IFERROR($J22*$F22/J$7,"") -> 0.52481803 | V22: =IFERROR($K22*$F22/K$7,"") -> 0.39008303 | W22: =IFERROR($L22*$F22/L$7,"") -> 0.24003065 | X22: =IFERROR($M22*$F22/M$7,"") -> 0.1702319 | Y22: =IFERROR($N22*$F22/N$7,"") -> 0.33193855 | Z22: =IFERROR($O22*$F22/O$7,"") -> 0.33184679 | AA22: =IFERROR($P22*$F22/P$7,"") -> 0.38723597
A23: AC | B23: Phelps Dodge CV/CV-FD-1C | 300 mm² | C23: 1 | D23: 300 | E23: 30 | F23: =PI()*E23^2/4 -> 706.85835 | G23: =IF(INT(0.4*G$7/$F23)>=3,INT(0.4*G$7/$F23),IF(INT(0.31*G$7/$F23)>=2,2,IF(0.53*G$7/$F23>=1,1,0))) -> 0 | H23: =IF(INT(0.4*H$7/$F23)>=3,INT(0.4*H$7/$F23),IF(INT(0.31*H$7/$F23)>=2,2,IF(0.53*H$7/$F23>=1,1,0))) -> 0 | I23: =IF(INT(0.4*I$7/$F23)>=3,INT(0.4*I$7/$F23),IF(INT(0.31*I$7/$F23)>=2,2,IF(0.53*I$7/$F23>=1,1,0))) -> 0 | J23: =IF(INT(0.4*J$7/$F23)>=3,INT(0.4*J$7/$F23),IF(INT(0.31*J$7/$F23)>=2,2,IF(0.53*J$7/$F23>=1,1,0))) -> 0 | K23: =IF(INT(0.4*K$7/$F23)>=3,INT(0.4*K$7/$F23),IF(INT(0.31*K$7/$F23)>=2,2,IF(0.53*K$7/$F23>=1,1,0))) -> 1 | L23: =IF(INT(0.4*L$7/$F23)>=3,INT(0.4*L$7/$F23),IF(INT(0.31*L$7/$F23)>=2,2,IF(0.53*L$7/$F23>=1,1,0))) -> 1 | M23: =IF(INT(0.4*M$7/$F23)>=3,INT(0.4*M$7/$F23),IF(INT(0.31*M$7/$F23)>=2,2,IF(0.53*M$7/$F23>=1,1,0))) -> 1 | N23: =IF(INT(0.4*N$7/$F23)>=3,INT(0.4*N$7/$F23),IF(INT(0.31*N$7/$F23)>=2,2,IF(0.53*N$7/$F23>=1,1,0))) -> 2 | ... P23: =IF(INT(0.4*P$7/$F23)>=3,INT(0.4*P$7/$F23),IF(INT(0.31*P$7/$F23)>=2,2,IF(0.53*P$7/$F23>=1,1,0))) -> 5 | R23: =IFERROR($G23*$F23/G$7,"") -> 0 | S23: =IFERROR($H23*$F23/H$7,"") -> 0 | T23: =IFERROR($I23*$F23/I$7,"") -> 0 | U23: =IFERROR($J23*$F23/J$7,"") -> 0 | V23: =IFERROR($K23*$F23/K$7,"") -> 0.48158399 | W23: =IFERROR($L23*$F23/L$7,"") -> 0.29633414 | X23: =IFERROR($M23*$F23/M$7,"") -> 0.21016284 | Y23: =IFERROR($N23*$F23/N$7,"") -> 0.27320045 | Z23: =IFERROR($O23*$F23/O$7,"") -> 0.30726555 | AA23: =IFERROR($P23*$F23/P$7,"") -> 0.39839091
A24: AC | B24: Phelps Dodge CV/CV-FD-1C | 400 mm² | C24: 1 | D24: 400 | E24: 33 | F24: =PI()*E24^2/4 -> 855.2986 | G24: =IF(INT(0.4*G$7/$F24)>=3,INT(0.4*G$7/$F24),IF(INT(0.31*G$7/$F24)>=2,2,IF(0.53*G$7/$F24>=1,1,0))) -> 0 | H24: =IF(INT(0.4*H$7/$F24)>=3,INT(0.4*H$7/$F24),IF(INT(0.31*H$7/$F24)>=2,2,IF(0.53*H$7/$F24>=1,1,0))) -> 0 | I24: =IF(INT(0.4*I$7/$F24)>=3,INT(0.4*I$7/$F24),IF(INT(0.31*I$7/$F24)>=2,2,IF(0.53*I$7/$F24>=1,1,0))) -> 0 | J24: =IF(INT(0.4*J$7/$F24)>=3,INT(0.4*J$7/$F24),IF(INT(0.31*J$7/$F24)>=2,2,IF(0.53*J$7/$F24>=1,1,0))) -> 0 | K24: =IF(INT(0.4*K$7/$F24)>=3,INT(0.4*K$7/$F24),IF(INT(0.31*K$7/$F24)>=2,2,IF(0.53*K$7/$F24>=1,1,0))) -> 0 | L24: =IF(INT(0.4*L$7/$F24)>=3,INT(0.4*L$7/$F24),IF(INT(0.31*L$7/$F24)>=2,2,IF(0.53*L$7/$F24>=1,1,0))) -> 1 | M24: =IF(INT(0.4*M$7/$F24)>=3,INT(0.4*M$7/$F24),IF(INT(0.31*M$7/$F24)>=2,2,IF(0.53*M$7/$F24>=1,1,0))) -> 1 | N24: =IF(INT(0.4*N$7/$F24)>=3,INT(0.4*N$7/$F24),IF(INT(0.31*N$7/$F24)>=2,2,IF(0.53*N$7/$F24>=1,1,0))) -> 1 | ... P24: =IF(INT(0.4*P$7/$F24)>=3,INT(0.4*P$7/$F24),IF(INT(0.31*P$7/$F24)>=2,2,IF(0.53*P$7/$F24>=1,1,0))) -> 4 | R24: =IFERROR($G24*$F24/G$7,"") -> 0 | S24: =IFERROR($H24*$F24/H$7,"") -> 0 | T24: =IFERROR($I24*$F24/I$7,"") -> 0 | U24: =IFERROR($J24*$F24/J$7,"") -> 0 | V24: =IFERROR($K24*$F24/K$7,"") -> 0 | W24: =IFERROR($L24*$F24/L$7,"") -> 0.35856431 | X24: =IFERROR($M24*$F24/M$7,"") -> 0.25429704 | Y24: =IFERROR($N24*$F24/N$7,"") -> 0.16528627 | Z24: =IFERROR($O24*$F24/O$7,"") -> 0.37179131 | AA24: =IFERROR($P24*$F24/P$7,"") -> 0.3856424
A25: AC | B25: Phelps Dodge CV/CV-FD-1C | 500 mm² | C25: 1 | D25: 500 | E25: 37 | F25: =PI()*E25^2/4 -> 1075.2101 | G25: =IF(INT(0.4*G$7/$F25)>=3,INT(0.4*G$7/$F25),IF(INT(0.31*G$7/$F25)>=2,2,IF(0.53*G$7/$F25>=1,1,0))) -> 0 | H25: =IF(INT(0.4*H$7/$F25)>=3,INT(0.4*H$7/$F25),IF(INT(0.31*H$7/$F25)>=2,2,IF(0.53*H$7/$F25>=1,1,0))) -> 0 | I25: =IF(INT(0.4*I$7/$F25)>=3,INT(0.4*I$7/$F25),IF(INT(0.31*I$7/$F25)>=2,2,IF(0.53*I$7/$F25>=1,1,0))) -> 0 | J25: =IF(INT(0.4*J$7/$F25)>=3,INT(0.4*J$7/$F25),IF(INT(0.31*J$7/$F25)>=2,2,IF(0.53*J$7/$F25>=1,1,0))) -> 0 | K25: =IF(INT(0.4*K$7/$F25)>=3,INT(0.4*K$7/$F25),IF(INT(0.31*K$7/$F25)>=2,2,IF(0.53*K$7/$F25>=1,1,0))) -> 0 | L25: =IF(INT(0.4*L$7/$F25)>=3,INT(0.4*L$7/$F25),IF(INT(0.31*L$7/$F25)>=2,2,IF(0.53*L$7/$F25>=1,1,0))) -> 1 | M25: =IF(INT(0.4*M$7/$F25)>=3,INT(0.4*M$7/$F25),IF(INT(0.31*M$7/$F25)>=2,2,IF(0.53*M$7/$F25>=1,1,0))) -> 1 | N25: =IF(INT(0.4*N$7/$F25)>=3,INT(0.4*N$7/$F25),IF(INT(0.31*N$7/$F25)>=2,2,IF(0.53*N$7/$F25>=1,1,0))) -> 1 | ... P25: =IF(INT(0.4*P$7/$F25)>=3,INT(0.4*P$7/$F25),IF(INT(0.31*P$7/$F25)>=2,2,IF(0.53*P$7/$F25>=1,1,0))) -> 3 | R25: =IFERROR($G25*$F25/G$7,"") -> 0 | S25: =IFERROR($H25*$F25/H$7,"") -> 0 | T25: =IFERROR($I25*$F25/I$7,"") -> 0 | U25: =IFERROR($J25*$F25/J$7,"") -> 0 | V25: =IFERROR($K25*$F25/K$7,"") -> 0 | W25: =IFERROR($L25*$F25/L$7,"") -> 0.45075715 | X25: =IFERROR($M25*$F25/M$7,"") -> 0.31968103 | Y25: =IFERROR($N25*$F25/N$7,"") -> 0.20778412 | Z25: =IFERROR($O25*$F25/O$7,"") -> 0.15579501 | AA25: =IFERROR($P25*$F25/P$7,"") -> 0.36359811
A26: AC | B26: Phelps Dodge CV/CV-FD-1C | 630 mm² | C26: 1 | D26: 630 | E26: 41 | F26: =PI()*E26^2/4 -> 1320.2543 | G26: =IF(INT(0.4*G$7/$F26)>=3,INT(0.4*G$7/$F26),IF(INT(0.31*G$7/$F26)>=2,2,IF(0.53*G$7/$F26>=1,1,0))) -> 0 | H26: =IF(INT(0.4*H$7/$F26)>=3,INT(0.4*H$7/$F26),IF(INT(0.31*H$7/$F26)>=2,2,IF(0.53*H$7/$F26>=1,1,0))) -> 0 | I26: =IF(INT(0.4*I$7/$F26)>=3,INT(0.4*I$7/$F26),IF(INT(0.31*I$7/$F26)>=2,2,IF(0.53*I$7/$F26>=1,1,0))) -> 0 | J26: =IF(INT(0.4*J$7/$F26)>=3,INT(0.4*J$7/$F26),IF(INT(0.31*J$7/$F26)>=2,2,IF(0.53*J$7/$F26>=1,1,0))) -> 0 | K26: =IF(INT(0.4*K$7/$F26)>=3,INT(0.4*K$7/$F26),IF(INT(0.31*K$7/$F26)>=2,2,IF(0.53*K$7/$F26>=1,1,0))) -> 0 | L26: =IF(INT(0.4*L$7/$F26)>=3,INT(0.4*L$7/$F26),IF(INT(0.31*L$7/$F26)>=2,2,IF(0.53*L$7/$F26>=1,1,0))) -> 0 | M26: =IF(INT(0.4*M$7/$F26)>=3,INT(0.4*M$7/$F26),IF(INT(0.31*M$7/$F26)>=2,2,IF(0.53*M$7/$F26>=1,1,0))) -> 1 | N26: =IF(INT(0.4*N$7/$F26)>=3,INT(0.4*N$7/$F26),IF(INT(0.31*N$7/$F26)>=2,2,IF(0.53*N$7/$F26>=1,1,0))) -> 1 | ... P26: =IF(INT(0.4*P$7/$F26)>=3,INT(0.4*P$7/$F26),IF(INT(0.31*P$7/$F26)>=2,2,IF(0.53*P$7/$F26>=1,1,0))) -> 2 | R26: =IFERROR($G26*$F26/G$7,"") -> 0 | S26: =IFERROR($H26*$F26/H$7,"") -> 0 | T26: =IFERROR($I26*$F26/I$7,"") -> 0 | U26: =IFERROR($J26*$F26/J$7,"") -> 0 | V26: =IFERROR($K26*$F26/K$7,"") -> 0 | W26: =IFERROR($L26*$F26/L$7,"") -> 0 | X26: =IFERROR($M26*$F26/M$7,"") -> 0.39253748 | Y26: =IFERROR($N26*$F26/N$7,"") -> 0.25513887 | Z26: =IFERROR($O26*$F26/O$7,"") -> 0.19130125 | AA26: =IFERROR($P26*$F26/P$7,"") -> 0.29764228
A27: AC | B27: Phelps Dodge CV/CV-FD-2C | 10 mm² | C27: 2 | D27: 10 | E27: 16 | F27: =PI()*E27^2/4 -> 201.06193 | G27: =IF(INT(0.4*G$7/$F27)>=3,INT(0.4*G$7/$F27),IF(INT(0.31*G$7/$F27)>=2,2,IF(0.53*G$7/$F27>=1,1,0))) -> 0 | H27: =IF(INT(0.4*H$7/$F27)>=3,INT(0.4*H$7/$F27),IF(INT(0.31*H$7/$F27)>=2,2,IF(0.53*H$7/$F27>=1,1,0))) -> 1 | I27: =IF(INT(0.4*I$7/$F27)>=3,INT(0.4*I$7/$F27),IF(INT(0.31*I$7/$F27)>=2,2,IF(0.53*I$7/$F27>=1,1,0))) -> 1 | J27: =IF(INT(0.4*J$7/$F27)>=3,INT(0.4*J$7/$F27),IF(INT(0.31*J$7/$F27)>=2,2,IF(0.53*J$7/$F27>=1,1,0))) -> 1 | K27: =IF(INT(0.4*K$7/$F27)>=3,INT(0.4*K$7/$F27),IF(INT(0.31*K$7/$F27)>=2,2,IF(0.53*K$7/$F27>=1,1,0))) -> 2 | L27: =IF(INT(0.4*L$7/$F27)>=3,INT(0.4*L$7/$F27),IF(INT(0.31*L$7/$F27)>=2,2,IF(0.53*L$7/$F27>=1,1,0))) -> 4 | M27: =IF(INT(0.4*M$7/$F27)>=3,INT(0.4*M$7/$F27),IF(INT(0.31*M$7/$F27)>=2,2,IF(0.53*M$7/$F27>=1,1,0))) -> 6 | N27: =IF(INT(0.4*N$7/$F27)>=3,INT(0.4*N$7/$F27),IF(INT(0.31*N$7/$F27)>=2,2,IF(0.53*N$7/$F27>=1,1,0))) -> 10 | ... P27: =IF(INT(0.4*P$7/$F27)>=3,INT(0.4*P$7/$F27),IF(INT(0.31*P$7/$F27)>=2,2,IF(0.53*P$7/$F27>=1,1,0))) -> 17 | R27: =IFERROR($G27*$F27/G$7,"") -> 0 | S27: =IFERROR($H27*$F27/H$7,"") -> 0.51294834 | T27: =IFERROR($I27*$F27/I$7,"") -> 0.31628269 | U27: =IFERROR($J27*$F27/J$7,"") -> 0.18429824 | V27: =IFERROR($K27*$F27/K$7,"") -> 0.27396778 | W27: =IFERROR($L27*$F27/L$7,"") -> 0.3371624 | X27: =IFERROR($M27*$F27/M$7,"") -> 0.35867791 | Y27: =IFERROR($N27*$F27/N$7,"") -> 0.38855175 | Z27: =IFERROR($O27*$F27/O$7,"") -> 0.37873324 | AA27: =IFERROR($P27*$F27/P$7,"") -> 0.38528828
A28: AC | B28: Phelps Dodge CV/CV-FD-2C | 16 mm² | C28: 2 | D28: 16 | E28: 18 | F28: =PI()*E28^2/4 -> 254.469 | G28: =IF(INT(0.4*G$7/$F28)>=3,INT(0.4*G$7/$F28),IF(INT(0.31*G$7/$F28)>=2,2,IF(0.53*G$7/$F28>=1,1,0))) -> 0 | H28: =IF(INT(0.4*H$7/$F28)>=3,INT(0.4*H$7/$F28),IF(INT(0.31*H$7/$F28)>=2,2,IF(0.53*H$7/$F28>=1,1,0))) -> 0 | I28: =IF(INT(0.4*I$7/$F28)>=3,INT(0.4*I$7/$F28),IF(INT(0.31*I$7/$F28)>=2,2,IF(0.53*I$7/$F28>=1,1,0))) -> 1 | J28: =IF(INT(0.4*J$7/$F28)>=3,INT(0.4*J$7/$F28),IF(INT(0.31*J$7/$F28)>=2,2,IF(0.53*J$7/$F28>=1,1,0))) -> 1 | K28: =IF(INT(0.4*K$7/$F28)>=3,INT(0.4*K$7/$F28),IF(INT(0.31*K$7/$F28)>=2,2,IF(0.53*K$7/$F28>=1,1,0))) -> 1 | L28: =IF(INT(0.4*L$7/$F28)>=3,INT(0.4*L$7/$F28),IF(INT(0.31*L$7/$F28)>=2,2,IF(0.53*L$7/$F28>=1,1,0))) -> 3 | M28: =IF(INT(0.4*M$7/$F28)>=3,INT(0.4*M$7/$F28),IF(INT(0.31*M$7/$F28)>=2,2,IF(0.53*M$7/$F28>=1,1,0))) -> 5 | N28: =IF(INT(0.4*N$7/$F28)>=3,INT(0.4*N$7/$F28),IF(INT(0.31*N$7/$F28)>=2,2,IF(0.53*N$7/$F28>=1,1,0))) -> 8 | ... P28: =IF(INT(0.4*P$7/$F28)>=3,INT(0.4*P$7/$F28),IF(INT(0.31*P$7/$F28)>=2,2,IF(0.53*P$7/$F28>=1,1,0))) -> 13 | R28: =IFERROR($G28*$F28/G$7,"") -> 0 | S28: =IFERROR($H28*$F28/H$7,"") -> 0 | T28: =IFERROR($I28*$F28/I$7,"") -> 0.40029528 | U28: =IFERROR($J28*$F28/J$7,"") -> 0.23325246 | V28: =IFERROR($K28*$F28/K$7,"") -> 0.17337024 | W28: =IFERROR($L28*$F28/L$7,"") -> 0.32004087 | X28: =IFERROR($M28*$F28/M$7,"") -> 0.37829311 | Y28: =IFERROR($N28*$F28/N$7,"") -> 0.39340865 | Z28: =IFERROR($O28*$F28/O$7,"") -> 0.36871866 | AA28: =IFERROR($P28*$F28/P$7,"") -> 0.37289389
A29: AC | B29: Phelps Dodge CV/CV-FD-2C | 25 mm² | C29: 2 | D29: 25 | E29: 21 | F29: =PI()*E29^2/4 -> 346.36059 | G29: =IF(INT(0.4*G$7/$F29)>=3,INT(0.4*G$7/$F29),IF(INT(0.31*G$7/$F29)>=2,2,IF(0.53*G$7/$F29>=1,1,0))) -> 0 | H29: =IF(INT(0.4*H$7/$F29)>=3,INT(0.4*H$7/$F29),IF(INT(0.31*H$7/$F29)>=2,2,IF(0.53*H$7/$F29>=1,1,0))) -> 0 | I29: =IF(INT(0.4*I$7/$F29)>=3,INT(0.4*I$7/$F29),IF(INT(0.31*I$7/$F29)>=2,2,IF(0.53*I$7/$F29>=1,1,0))) -> 0 | J29: =IF(INT(0.4*J$7/$F29)>=3,INT(0.4*J$7/$F29),IF(INT(0.31*J$7/$F29)>=2,2,IF(0.53*J$7/$F29>=1,1,0))) -> 1 | K29: =IF(INT(0.4*K$7/$F29)>=3,INT(0.4*K$7/$F29),IF(INT(0.31*K$7/$F29)>=2,2,IF(0.53*K$7/$F29>=1,1,0))) -> 1 | L29: =IF(INT(0.4*L$7/$F29)>=3,INT(0.4*L$7/$F29),IF(INT(0.31*L$7/$F29)>=2,2,IF(0.53*L$7/$F29>=1,1,0))) -> 2 | M29: =IF(INT(0.4*M$7/$F29)>=3,INT(0.4*M$7/$F29),IF(INT(0.31*M$7/$F29)>=2,2,IF(0.53*M$7/$F29>=1,1,0))) -> 3 | N29: =IF(INT(0.4*N$7/$F29)>=3,INT(0.4*N$7/$F29),IF(INT(0.31*N$7/$F29)>=2,2,IF(0.53*N$7/$F29>=1,1,0))) -> 5 | ... P29: =IF(INT(0.4*P$7/$F29)>=3,INT(0.4*P$7/$F29),IF(INT(0.31*P$7/$F29)>=2,2,IF(0.53*P$7/$F29>=1,1,0))) -> 10 | R29: =IFERROR($G29*$F29/G$7,"") -> 0 | S29: =IFERROR($H29*$F29/H$7,"") -> 0 | T29: =IFERROR($I29*$F29/I$7,"") -> 0 | U29: =IFERROR($J29*$F29/J$7,"") -> 0.31748251 | V29: =IFERROR($K29*$F29/K$7,"") -> 0.23597615 | W29: =IFERROR($L29*$F29/L$7,"") -> 0.29040746 | X29: =IFERROR($M29*$F29/M$7,"") -> 0.30893937 | Y29: =IFERROR($N29*$F29/N$7,"") -> 0.33467055 | Z29: =IFERROR($O29*$F29/O$7,"") -> 0.35130694 | AA29: =IFERROR($P29*$F29/P$7,"") -> 0.39042309
A30: AC | B30: Phelps Dodge CV/CV-FD-2C | 35 mm² | C30: 2 | D30: 35 | E30: 23 | F30: =PI()*E30^2/4 -> 415.47563 | G30: =IF(INT(0.4*G$7/$F30)>=3,INT(0.4*G$7/$F30),IF(INT(0.31*G$7/$F30)>=2,2,IF(0.53*G$7/$F30>=1,1,0))) -> 0 | H30: =IF(INT(0.4*H$7/$F30)>=3,INT(0.4*H$7/$F30),IF(INT(0.31*H$7/$F30)>=2,2,IF(0.53*H$7/$F30>=1,1,0))) -> 0 | I30: =IF(INT(0.4*I$7/$F30)>=3,INT(0.4*I$7/$F30),IF(INT(0.31*I$7/$F30)>=2,2,IF(0.53*I$7/$F30>=1,1,0))) -> 0 | J30: =IF(INT(0.4*J$7/$F30)>=3,INT(0.4*J$7/$F30),IF(INT(0.31*J$7/$F30)>=2,2,IF(0.53*J$7/$F30>=1,1,0))) -> 1 | K30: =IF(INT(0.4*K$7/$F30)>=3,INT(0.4*K$7/$F30),IF(INT(0.31*K$7/$F30)>=2,2,IF(0.53*K$7/$F30>=1,1,0))) -> 1 | L30: =IF(INT(0.4*L$7/$F30)>=3,INT(0.4*L$7/$F30),IF(INT(0.31*L$7/$F30)>=2,2,IF(0.53*L$7/$F30>=1,1,0))) -> 1 | M30: =IF(INT(0.4*M$7/$F30)>=3,INT(0.4*M$7/$F30),IF(INT(0.31*M$7/$F30)>=2,2,IF(0.53*M$7/$F30>=1,1,0))) -> 3 | N30: =IF(INT(0.4*N$7/$F30)>=3,INT(0.4*N$7/$F30),IF(INT(0.31*N$7/$F30)>=2,2,IF(0.53*N$7/$F30>=1,1,0))) -> 4 | ... P30: =IF(INT(0.4*P$7/$F30)>=3,INT(0.4*P$7/$F30),IF(INT(0.31*P$7/$F30)>=2,2,IF(0.53*P$7/$F30>=1,1,0))) -> 8 | R30: =IFERROR($G30*$F30/G$7,"") -> 0 | S30: =IFERROR($H30*$F30/H$7,"") -> 0 | T30: =IFERROR($I30*$F30/I$7,"") -> 0 | U30: =IFERROR($J30*$F30/J$7,"") -> 0.38083503 | V30: =IFERROR($K30*$F30/K$7,"") -> 0.28306437 | W30: =IFERROR($L30*$F30/L$7,"") -> 0.17417862 | X30: =IFERROR($M30*$F30/M$7,"") -> 0.37058714 | Y30: =IFERROR($N30*$F30/N$7,"") -> 0.32116231 | Z30: =IFERROR($O30*$F30/O$7,"") -> 0.36120772 | AA30: =IFERROR($P30*$F30/P$7,"") -> 0.37466452
A31: AC | B31: Phelps Dodge CV/CV-FD-2C | 50 mm² | C31: 2 | D31: 50 | E31: 25 | F31: =PI()*E31^2/4 -> 490.87385 | G31: =IF(INT(0.4*G$7/$F31)>=3,INT(0.4*G$7/$F31),IF(INT(0.31*G$7/$F31)>=2,2,IF(0.53*G$7/$F31>=1,1,0))) -> 0 | H31: =IF(INT(0.4*H$7/$F31)>=3,INT(0.4*H$7/$F31),IF(INT(0.31*H$7/$F31)>=2,2,IF(0.53*H$7/$F31>=1,1,0))) -> 0 | I31: =IF(INT(0.4*I$7/$F31)>=3,INT(0.4*I$7/$F31),IF(INT(0.31*I$7/$F31)>=2,2,IF(0.53*I$7/$F31>=1,1,0))) -> 0 | J31: =IF(INT(0.4*J$7/$F31)>=3,INT(0.4*J$7/$F31),IF(INT(0.31*J$7/$F31)>=2,2,IF(0.53*J$7/$F31>=1,1,0))) -> 1 | K31: =IF(INT(0.4*K$7/$F31)>=3,INT(0.4*K$7/$F31),IF(INT(0.31*K$7/$F31)>=2,2,IF(0.53*K$7/$F31>=1,1,0))) -> 1 | L31: =IF(INT(0.4*L$7/$F31)>=3,INT(0.4*L$7/$F31),IF(INT(0.31*L$7/$F31)>=2,2,IF(0.53*L$7/$F31>=1,1,0))) -> 1 | M31: =IF(INT(0.4*M$7/$F31)>=3,INT(0.4*M$7/$F31),IF(INT(0.31*M$7/$F31)>=2,2,IF(0.53*M$7/$F31>=1,1,0))) -> 2 | N31: =IF(INT(0.4*N$7/$F31)>=3,INT(0.4*N$7/$F31),IF(INT(0.31*N$7/$F31)>=2,2,IF(0.53*N$7/$F31>=1,1,0))) -> 4 | ... P31: =IF(INT(0.4*P$7/$F31)>=3,INT(0.4*P$7/$F31),IF(INT(0.31*P$7/$F31)>=2,2,IF(0.53*P$7/$F31>=1,1,0))) -> 7 | R31: =IFERROR($G31*$F31/G$7,"") -> 0 | S31: =IFERROR($H31*$F31/H$7,"") -> 0 | T31: =IFERROR($I31*$F31/I$7,"") -> 0 | U31: =IFERROR($J31*$F31/J$7,"") -> 0.44994687 | V31: =IFERROR($K31*$F31/K$7,"") -> 0.33443332 | W31: =IFERROR($L31*$F31/L$7,"") -> 0.2057876 | X31: =IFERROR($M31*$F31/M$7,"") -> 0.29189283 | Y31: =IFERROR($N31*$F31/N$7,"") -> 0.37944507 | Z31: =IFERROR($O31*$F31/O$7,"") -> 0.35563142 | AA31: =IFERROR($P31*$F31/P$7,"") -> 0.3873245
... A65: AC | B65: Phelps Dodge CV/CV-FD-4C | 400 mm² | C65: 4 | D65: 400 | E65: 74 | F65: =PI()*E65^2/4 -> 4300.8403 | G65: =IF(INT(0.4*G$7/$F65)>=3,INT(0.4*G$7/$F65),IF(INT(0.31*G$7/$F65)>=2,2,IF(0.53*G$7/$F65>=1,1,0))) -> 0 | H65: =IF(INT(0.4*H$7/$F65)>=3,INT(0.4*H$7/$F65),IF(INT(0.31*H$7/$F65)>=2,2,IF(0.53*H$7/$F65>=1,1,0))) -> 0 | I65: =IF(INT(0.4*I$7/$F65)>=3,INT(0.4*I$7/$F65),IF(INT(0.31*I$7/$F65)>=2,2,IF(0.53*I$7/$F65>=1,1,0))) -> 0 | J65: =IF(INT(0.4*J$7/$F65)>=3,INT(0.4*J$7/$F65),IF(INT(0.31*J$7/$F65)>=2,2,IF(0.53*J$7/$F65>=1,1,0))) -> 0 | K65: =IF(INT(0.4*K$7/$F65)>=3,INT(0.4*K$7/$F65),IF(INT(0.31*K$7/$F65)>=2,2,IF(0.53*K$7/$F65>=1,1,0))) -> 0 | L65: =IF(INT(0.4*L$7/$F65)>=3,INT(0.4*L$7/$F65),IF(INT(0.31*L$7/$F65)>=2,2,IF(0.53*L$7/$F65>=1,1,0))) -> 0 | M65: =IF(INT(0.4*M$7/$F65)>=3,INT(0.4*M$7/$F65),IF(INT(0.31*M$7/$F65)>=2,2,IF(0.53*M$7/$F65>=1,1,0))) -> 0 | N65: =IF(INT(0.4*N$7/$F65)>=3,INT(0.4*N$7/$F65),IF(INT(0.31*N$7/$F65)>=2,2,IF(0.53*N$7/$F65>=1,1,0))) -> 0 | ... P65: =IF(INT(0.4*P$7/$F65)>=3,INT(0.4*P$7/$F65),IF(INT(0.31*P$7/$F65)>=2,2,IF(0.53*P$7/$F65>=1,1,0))) -> 1 | R65: =IFERROR($G65*$F65/G$7,"") -> 0 | S65: =IFERROR($H65*$F65/H$7,"") -> 0 | T65: =IFERROR($I65*$F65/I$7,"") -> 0 | U65: =IFERROR($J65*$F65/J$7,"") -> 0 | V65: =IFERROR($K65*$F65/K$7,"") -> 0 | W65: =IFERROR($L65*$F65/L$7,"") -> 0 | X65: =IFERROR($M65*$F65/M$7,"") -> 0 | Y65: =IFERROR($N65*$F65/N$7,"") -> 0 | Z65: =IFERROR($O65*$F65/O$7,"") -> 0 | AA65: =IFERROR($P65*$F65/P$7,"") -> 0.48479747
B67: กำหนดจากขนาดราง Wireway และดู MAX
A68: User-entry IMC cable mix | total cable area vs WST fill condition
A69: Enter cable type/CSA/OD/Qty per row. WST allowed fill uses TOTAL Qty in the mix: Qty 1 = 53%, Qty 2 = 31%, Qty 3 or more = 40%. Cores/cable is informational only.
A70: Line | B70: Cable type / model | C70: Cores / cable (info.) | D70: CSA (mm²) | E70: OD (mm) | F70: Qty | G70: Area / cable (mm²) | H70: Total cable area (mm²) | I70: IMC trade size | J70: IMC internal area (mm²) | K70: WST allowed fill (total Qty) | L70: Fill % = total cable area / conduit area | M70: WST match | N70: Engineering result | O70: Engineering note
A71: USER-001 | B71: Phelps Dodge CV/CV-FD-1C | 120 mm² | C71: 1 | D71: 4 | E71: =_xlfn.XLOOKUP(B71,$B$10:$B$65,$E$10:$E$65,0,0) -> 20 | F71: 4 | G71: =IF(E71="","",PI()*E71^2/4) -> 314.15927 | H71: =IF(OR(G71="",F71=""),"",G71*F71) -> 1256.6371 | I71: 1/2 in | J71: =IF(I71="1/2 in",$G$7,IF(I71="3/4 in",$H$7,IF(I71="1 in",$I$7,IF(I71="1-1/4 in",$J$7,IF(I71="1-1/2 in",$K$7,IF(I71="2 in",$L$7,IF(I71="2-1/2 in",$M$7,IF(I71="3 in",$N$7,IF(I71="3-1/2 in",$O$7,IF(I71="4 in",$P$7,"")))))))))) -> 230.1958 | K71: =IF(F71="","",IF(F71=1,0.53,IF(F71=2,0.31,0.4))) -> 0.4 | L71: =IF(OR(H71="",J71=""),"",H71/J71) -> 5.4589921 | M71: =IF(OR(L71="",K71=""),"",IF(L71<=K71,"PASS","FAIL")) -> FAIL | N71: =IF(M71="","REVIEW",IF(M71="PASS","USE / PASS","CHECK")) -> CHECK | O71: Example; total Qty rule; confirm exact OD and certified IMC ID
A72: USER-002 | C72: 1 | D72: 6 | E72: =_xlfn.XLOOKUP(B72,$B$10:$B$65,$E$10:$E$65,0,0) -> 0 | F72: 0 | G72: =IF(E72="","",PI()*E72^2/4) -> 0 | H72: =IF(OR(G72="",F72=""),"",G72*F72) -> 0 | I72: 1/2 in | J72: =IF(I72="1/2 in",$G$7,IF(I72="3/4 in",$H$7,IF(I72="1 in",$I$7,IF(I72="1-1/4 in",$J$7,IF(I72="1-1/2 in",$K$7,IF(I72="2 in",$L$7,IF(I72="2-1/2 in",$M$7,IF(I72="3 in",$N$7,IF(I72="3-1/2 in",$O$7,IF(I72="4 in",$P$7,"")))))))))) -> 230.1958 | K72: =IF(F72="","",IF(F72=1,0.53,IF(F72=2,0.31,0.4))) -> 0.4 | L72: =IF(OR(H72="",J72=""),"",H72/J72) -> 0 | M72: =IF(OR(L72="",K72=""),"",IF(L72<=K72,"PASS","FAIL")) -> PASS | N72: =IF(M72="","REVIEW",IF(M72="PASS","USE / PASS","CHECK")) -> USE / PASS | O72: Example; total Qty rule; confirm exact OD and certified IMC ID
A73: USER-003 | C73: 1 | D73: 10 | E73: =_xlfn.XLOOKUP(B73,$B$10:$B$65,$E$10:$E$65,0,0) -> 0 | F73: 0 | G73: =IF(E73="","",PI()*E73^2/4) -> 0 | H73: =IF(OR(G73="",F73=""),"",G73*F73) -> 0 | I73: 3/4 in | J73: =IF(I73="1/2 in",$G$7,IF(I73="3/4 in",$H$7,IF(I73="1 in",$I$7,IF(I73="1-1/4 in",$J$7,IF(I73="1-1/2 in",$K$7,IF(I73="2 in",$L$7,IF(I73="2-1/2 in",$M$7,IF(I73="3 in",$N$7,IF(I73="3-1/2 in",$O$7,IF(I73="4 in",$P$7,"")))))))))) -> 391.97306 | K73: =IF(F73="","",IF(F73=1,0.53,IF(F73=2,0.31,0.4))) -> 0.4 | L73: =IF(OR(H73="",J73=""),"",H73/J73) -> 0 | M73: =IF(OR(L73="",K73=""),"",IF(L73<=K73,"PASS","FAIL")) -> PASS | N73: =IF(M73="","REVIEW",IF(M73="PASS","USE / PASS","CHECK")) -> USE / PASS | O73: Example; total Qty rule; confirm exact OD and certified IMC ID
A74: USER-004 | C74: 2 | D74: 16 | E74: =_xlfn.XLOOKUP(B74,$B$10:$B$65,$E$10:$E$65,0,0) -> 0 | F74: 0 | G74: =IF(E74="","",PI()*E74^2/4) -> 0 | H74: =IF(OR(G74="",F74=""),"",G74*F74) -> 0 | I74: 1 in | J74: =IF(I74="1/2 in",$G$7,IF(I74="3/4 in",$H$7,IF(I74="1 in",$I$7,IF(I74="1-1/4 in",$J$7,IF(I74="1-1/2 in",$K$7,IF(I74="2 in",$L$7,IF(I74="2-1/2 in",$M$7,IF(I74="3 in",$N$7,IF(I74="3-1/2 in",$O$7,IF(I74="4 in",$P$7,"")))))))))) -> 635.70324 | K74: =IF(F74="","",IF(F74=1,0.53,IF(F74=2,0.31,0.4))) -> 0.4 | L74: =IF(OR(H74="",J74=""),"",H74/J74) -> 0 | M74: =IF(OR(L74="",K74=""),"",IF(L74<=K74,"PASS","FAIL")) -> PASS | N74: =IF(M74="","REVIEW",IF(M74="PASS","USE / PASS","CHECK")) -> USE / PASS | O74: Example; cores/cable shown only for information
A75: USER-005 | B75: AC Cable (THW) - G 70 sq.mm. | C75: 1 | D75: 25 | E75: 14.6 | F75: 1 | G75: =IF(E75="","",PI()*E75^2/4) -> 167.41547 | H75: =IF(OR(G75="",F75=""),"",G75*F75) -> 167.41547 | I75: 1 in | J75: =IF(I75="1/2 in",$G$7,IF(I75="3/4 in",$H$7,IF(I75="1 in",$I$7,IF(I75="1-1/4 in",$J$7,IF(I75="1-1/2 in",$K$7,IF(I75="2 in",$L$7,IF(I75="2-1/2 in",$M$7,IF(I75="3 in",$N$7,IF(I75="3-1/2 in",$O$7,IF(I75="4 in",$P$7,"")))))))))) -> 635.70324 | K75: =IF(F75="","",IF(F75=1,0.53,IF(F75=2,0.31,0.4))) -> 0.53 | L75: =IF(OR(H75="",J75=""),"",H75/J75) -> 0.26335476 | M75: =IF(OR(L75="",K75=""),"",IF(L75<=K75,"PASS","FAIL")) -> PASS | N75: =IF(M75="","REVIEW",IF(M75="PASS","USE / PASS","CHECK")) -> USE / PASS | O75: Free user-entry row; total Qty rule applies
...
